# AI辅助debug：从错误日志到解决方案

**作者**: Cline | **发布日期**: 2025-11-07 | **分类**: `AI工具链` `开发效率` `Debug` `软件质量`

**摘要**: 没什么比一段晦涩难懂、堆栈信息长达百行的错误日志更能摧毁一个开发者下午的好心情了。传统的Debug过程（猜测、打印日志、二分法定位）既耗时又痛苦。幸运的是，AI编程助手正在彻底改变这一古老的游戏。本文将通过一个真实的案例，带你体验一次现代化的、由AI驱动的Debug流程。我们将从一个典型的Python异步应用中遇到的`RuntimeError: Task attached to a different loop`错误出发，系统性地展示如何利用AI工具（如Phind, ChatGPT, Claude）将天书般的错误日志转化为清晰的行动指南，精准定位问题根源，并生成优雅的修复代码，最终将Debug从一门“玄学”变成一门高效的“科学”。

**SEO关键词**: AI辅助debug, 解决编程错误, Python asyncio, 错误日志分析, AI代码修复, 调试技巧, 软件bug

---

## 第1部分：故障现场——令人费解的`RuntimeError`

**场景**: 我们正在开发一个基于FastAPI和`aiohttp`的Python应用。其中一个功能是，应用在启动时需要从一个外部API获取初始化配置。为了不阻塞主应用启动，我们决定将其放在一个后台任务中执行。

**有问题的代码 (`main.py`)**:
```python
import asyncio
import aiohttp
from fastapi import FastAPI

app = FastAPI()

# 一个全局变量，用于存储从外部获取的配置
APP_CONFIG = {}

async def fetch_remote_config():
    """
    一个模拟的异步函数，用于获取远程配置。
    """
    print("Starting to fetch remote configuration...")
    # 在真实应用中，这里可能会是一个数据库调用或外部API请求
    await asyncio.sleep(5) # 模拟网络延迟
    config_data = {"feature_a_enabled": True, "timeout": 50}
    print("Configuration fetched successfully.")
    return config_data

async def background_config_loader():
    """
    后台任务，用于加载配置并赋值给全局变量。
    """
    global APP_CONFIG
    # 这里犯了一个常见的错误：直接调用异步函数，但没有await它
    task = fetch_remote_config() 
    # 假设开发者忘记了await，或者错误地认为这样就是启动了后台任务
    # ... 一些其他的后台逻辑 ...
    print("Background task finished its logic (but config is not ready).")
    # 为了让问题暴露，我们在任务结束前等待task
    await task


@app.on_event("startup")
async def on_startup():
    """
    FastAPI的启动事件处理器。
    """
    print("Application startup event triggered.")
    # 意图是启动一个不阻塞主线程的后台任务
    asyncio.create_task(background_config_loader())
    print("Background config loader task created.")


@app.get("/status")
async def get_status():
    return {"status": "ok", "config_loaded": bool(APP_CONFIG)}
```

**运行应用**:
使用`uvicorn main:app --reload`启动应用。在最初的几秒钟，一切看起来都正常。然而，5秒钟后，终端突然抛出了一个可怕的错误：

**错误日志**:
```
ERROR:    Exception in ASGI application
Traceback (most recent call last):
  ... (省略部分FastAPI和Uvicorn的内部堆栈)
  File "/usr/lib/python3.9/asyncio/tasks.py", line 492, in wait_for
    return fut.result()
  File "/usr/lib/python3.9/asyncio/tasks.py", line 287, in result
    raise self._exception
  File "/usr/lib/python3.9/asyncio/tasks.py", line 256, in _step
    result = coro.send(None)
  File "main.py", line 28, in background_config_loader
    await task
RuntimeError: Task <Task pending name='Task-2' coro=<fetch_remote_config() running at main.py:12>> attached to a different loop
```

对于不熟悉`asyncio`内部机制的开发者来说，`RuntimeError: Task attached to a different loop` 这条信息非常令人困惑。“不同的loop”是什么意思？我的代码里只有一个事件循环啊？

---

## 第2部分：AI登场——从错误日志到洞察

现在，我们把完整的错误日志复制下来，交给AI。这里我们以[Phind](https://www.phind.com/)为例，它是一个专注于开发者问题的AI搜索引擎。

**向Phind提问 (Prompt)**:
> I'm getting a `RuntimeError: Task attached to a different loop` in my FastAPI application. Here is my code and the full traceback. Can you explain what this error means and how to fix it?
>
> **Code:**
> ```python
> # ... (粘贴完整的main.py代码) ...
> ```
>
> **Traceback:**
> ```
> # ... (粘贴完整的错误日志) ...
> ```

**Phind (或ChatGPT/Claude) 的分析与解释 (摘要)**:

> ### Explanation of the Error
>
> The error `RuntimeError: Task attached to a different loop` almost always occurs in an `asyncio` context when you try to `await` a task or coroutine that was created in a different event loop from the one that is currently running.
>
> In your case, the problem lies in this line within `background_config_loader`:
> ```python
> task = fetch_remote_config()
> ```
> When you call an `async` function like `fetch_remote_config()` **without `await`**, it doesn't run the function. Instead, it creates a **coroutine object**. This coroutine object implicitly "binds" to the event loop that is active **at the moment of its creation**.
>
> The `on_startup` event in FastAPI is run by `uvicorn`, which manages its own event loop. The coroutine object for `fetch_remote_config` was created inside the `background_config_loader` task, which is running on `uvicorn`'s loop.
>
> However, some async libraries (or how `asyncio.sleep` is implemented internally) might interact with the event loop in a way that when you later `await task`, the context has subtly changed, or the task object is perceived as belonging to a different loop instance, especially across different library boundaries (like FastAPI and `asyncio`).
>
> The most direct cause is that the `task` object was created but not immediately awaited or turned into a `Task` in the correct context.
>
> ### How to Fix It
>
> The core issue is that you are not creating an `asyncio.Task` correctly. You should use `asyncio.create_task()` to schedule the coroutine to run on the current event loop.
>
> **Incorrect:**
> ```python
> # This just creates a coroutine object, doesn't schedule it
> task = fetch_remote_config()
> await task
> ```
>
> **Correct:**
> ```python
> # This schedules the coroutine to run as a task in the current loop
> task = asyncio.create_task(fetch_remote_config())
> await task
> ```
>
> So, your `background_config_loader` function should be changed to:
>
> ```python
---
> # **Suggested Fix:**
> async def background_config_loader():
>     global APP_CONFIG
>     print("Creating background task to fetch config...")
>     config_task = asyncio.create_task(fetch_remote_config())
>     
>     # Now you can do other stuff while the task runs in the background
>     print("Doing other background work...")
>     await asyncio.sleep(1) 
>
>     # Wait for the config task to complete and get its result
>     APP_CONFIG = await config_task
>     print("Background task finished and config is set.")
> ```

**AI洞察总结**:
1.  **清晰地解释了“不同loop”的本质**: AI指出了问题根源在于`await`了一个“裸露的”协程对象，而不是一个被正确调度的`Task`。
2.  **精准定位问题代码**: `task = fetch_remote_config()`。
3.  **提供明确的修复方案**: 用`asyncio.create_task()`来替代直接调用。
4.  **给出可以直接复制粘贴的修复后代码**。

---

## 第3部分：应用修复与验证

根据AI的建议，我们修改`main.py`。

**修复后的代码 (`main.py`)**:
```python
import asyncio
import aiohttp
from fastapi import FastAPI

app = FastAPI()

APP_CONFIG = {}

async def fetch_remote_config():
    print("Starting to fetch remote configuration...")
    await asyncio.sleep(5)
    config_data = {"feature_a_enabled": True, "timeout": 50}
    print("Configuration fetched successfully.")
    return config_data

async def background_config_loader():
    global APP_CONFIG
    print("Creating background task to fetch config...")
    # 应用AI的修复：使用create_task
    config_task = asyncio.create_task(fetch_remote_config())
    
    print("Doing other background work while config is loading...")
    await asyncio.sleep(1) # 模拟其他工作
    
    # 等待任务完成并获取结果
    loaded_config = await config_task
    APP_CONFIG = loaded_config
    print("Background task finished and config is now set.")


@app.on_event("startup")
async def on_startup():
    print("Application startup event triggered.")
    asyncio.create_task(background_config_loader())
    print("Background config loader task created.")


@app.get("/status")
async def get_status():
    return {"status": "ok", "config_loaded": bool(APP_CONFIG)}
```

**再次运行和验证**:
1.  启动`uvicorn`，应用正常启动，没有报错。
2.  应用启动后立即访问`http://127.0.0.1:8000/status`，得到 `{"status":"ok","config_loaded":false}`。
3.  等待约5秒后，再次访问`http://127.0.0.1:8000/status`，得到 `{"status":"ok","config_loaded":true}`。

终端日志也显示了正确的执行顺序：
```
Application startup event triggered.
Background config loader task created.
Creating background task to fetch config...
Doing other background work while config is loading...
Starting to fetch remote configuration...
(等待5秒)
Configuration fetched successfully.
Background task finished and config is now set.
```
Bug被完美修复。

---

## 第4部分：反思与学习：将知识内化

AI不仅修复了Bug，更重要的是，它提供了一个学习的机会。我们可以追问AI，以深化理解。

**追问Prompt**:
> "Thanks, that fixed it! Can you elaborate on the difference between `my_coro()` and `asyncio.create_task(my_coro())`? Why does one cause a loop error and the other doesn't?"

**AI的深入解释 (摘要)**:
> `my_coro()`: This simply **creates a coroutine object**. It's a blueprint for a task, like a recipe for a cake. It hasn't been baked yet. The coroutine is "inert" and does nothing on its own. It implicitly captures a reference to the event loop that was active at the moment of its creation.
>
> `asyncio.create_task(my_coro())`: This takes the coroutine object and **schedules it to be run on the active event loop**. It returns a `Task` object, which is a wrapper around your coroutine. The event loop is now aware of this task and will start executing it as soon as it gets a chance (i.e., on the next tick of the loop).
>
> The `RuntimeError` happens because `await` expects to work with tasks or coroutines that are managed by the **currently running** event loop. When you create a bare coroutine and then `await` it much later in a complex application stack (like inside FastAPI/Uvicorn), the internal state or loop references can become mismatched, leading the runtime to think the task belongs to a different (or now-defunct) loop context.
>
> `asyncio.create_task` is the official, safe way to say "Hey, event loop, please take this coroutine and run it for me." This ensures the task is properly registered and managed within the correct loop context, preventing the error.

---

## 结论：AI时代的Debug新范式

这次经历向我们展示了AI辅助Debug的典型流程：

1.  **遭遇错误 -> 复制日志**: 不要害怕复杂的错误。完整地复制`Traceback`是第一步。
2.  **AI解释 -> 理解原因**: 将日志和相关代码喂给AI，让它将机器语言翻译成人类可以理解的原因分析。
3.  **AI修复 -> 应用代码**: 获取AI建议的修复方案，理解其背后的原理，然后应用到你的代码中。
4.  **验证 -> 确认修复**: 编写或运行测试来验证Bug是否已解决。
5.  **追问 -> 内化知识**: 利用AI作为一个永不疲倦的导师，深入探究问题的本质，防止未来再犯同样的错误。

在AI的帮助下，Debug不再是一场与机器的“搏斗”，而更像是一场与专家的“对话”。这种新范式不仅极大地提升了我们解决问题的效率，更加速了我们作为开发者的学习和成长。
